2024-01-05 22:57:00,923 ERROR: Error in home route: The current Flask app is not registered with this 'SQLAlchemy' instance. Did you forget to call 'init_app', or did you create multiple 'SQLAlchemy' instances? [in /Users/prajwal/Developer/Local Images Classification/app/routes.py:13]
Traceback (most recent call last):
  File "/Users/prajwal/Developer/Local Images Classification/app/routes.py", line 10, in home
    annotations = Annotation.query.all()
  File "/Users/prajwal/opt/anaconda3/envs/venv/lib/python3.8/site-packages/sqlalchemy/orm/query.py", line 2693, in all
    return self._iter().all()  # type: ignore
  File "/Users/prajwal/opt/anaconda3/envs/venv/lib/python3.8/site-packages/sqlalchemy/orm/query.py", line 2847, in _iter
    result: Union[ScalarResult[_T], Result[_T]] = self.session.execute(
  File "/Users/prajwal/opt/anaconda3/envs/venv/lib/python3.8/site-packages/sqlalchemy/orm/session.py", line 2308, in execute
    return self._execute_internal(
  File "/Users/prajwal/opt/anaconda3/envs/venv/lib/python3.8/site-packages/sqlalchemy/orm/session.py", line 2178, in _execute_internal
    bind = self.get_bind(**bind_arguments)
  File "/Users/prajwal/opt/anaconda3/envs/venv/lib/python3.8/site-packages/flask_sqlalchemy/session.py", line 53, in get_bind
    engines = self._db.engines
  File "/Users/prajwal/opt/anaconda3/envs/venv/lib/python3.8/site-packages/flask_sqlalchemy/extension.py", line 690, in engines
    raise RuntimeError(
RuntimeError: The current Flask app is not registered with this 'SQLAlchemy' instance. Did you forget to call 'init_app', or did you create multiple 'SQLAlchemy' instances?
